<?xml version="1.0"?>
<robot xmlns:xacro="http://www.ros.org/wiki/xacro">

    <!--Dinamic
    var using xacro-->
    <xacro:property name="base_length" value="0.7" />
    <xacro:property name="base_width" value="0.75" />
    <xacro:property name="base_height" value="0.2" />
    <xacro:property name="wheel_radius" value="0.1" />
    <xacro:property name="wheel_length" value="0.05" />
    <xacro:property name="upper_base_length" value="0.4" />
    <xacro:property name="upper_base_width" value="0.4" />
    <xacro:property name="upper_base_height" value="0.8" />
    <!-- Define links -->
    <link name="base_footprint" />

    <link name="base_link">
        <inertial>
            <origin xyz="-0.0515854572028516 -0.000276126131789067 0.231920765641826" rpy="0 0 0" />
            <mass value="6.09418598920086" />
            <inertia ixx="0.108552021192883" ixy="-1.79528142341275E-06" ixz="-1.53088966310458E-06"
                iyy="0.08089844882398" iyz="-3.73213864653515E-07" izz="0.161058476654867" />
        </inertial>
        <visual>
            <origin xyz="0 0 0" rpy="0 0 0" />
            <geometry>
                <mesh filename="package://my_robot_description/meshes/base_link.STL" />
            </geometry>
            <material name="slategreen">
                <color rgba="0.396078431372549 0.5529411764705883 0.42745098039215684 1.0" />
            </material>
        </visual>
        <collision>
            <origin xyz="0 0 0" rpy="0 0 0" />
            <geometry>
                <mesh filename="package://my_robot_description/meshes/base_link.STL" />
            </geometry>
        </collision>
    </link>
    <gazebo reference="base_link">
        <material>Gazebo/Blue</material>
    </gazebo>
    <!--Function
    with xacro-->
    <link name="left_wheel_link" type="continuous">
        <inertial>
            <origin xyz="-0.00033068 0.00034718 -0.011299" rpy="0 0 0" />
            <mass value="1.0707" />
            <inertia ixx="0.0032564" ixy="-2.9602E-08" ixz="-1.0029E-08" iyy="0.0032565"
                iyz="4.0974E-08" izz="0.0062145" />
        </inertial>
        <visual>
            <origin xyz="0 0 0" rpy="0 0 0" />
            <geometry>
                <cylinder radius="0.1" length="0.05" />
            </geometry>
            <material name="black">
                <color rgba="0.0 0.0 0.0 1.0" />
            </material>
        </visual>
        <collision>
            <origin xyz="0 0 0" rpy="0 0 0" />
            <geometry>
                <cylinder radius="0.1" length="0.05" />
            </geometry>
        </collision>
    </link>

    <link name="right_wheel_link" type="continuous">
        <inertial>
            <origin xyz="-4.8407E-05 -0.0004779 0.0112" rpy="0 0 0" />
            <mass value="1.0707" />
            <inertia ixx="0.0032565" ixy="-4.2222E-08" ixz="-3.7763E-08" iyy="0.0032564"
                iyz="1.8799E-08" izz="0.0062145" />
        </inertial>
        <visual>
            <origin xyz="0 0 0" rpy="0 0 0" />
            <geometry>
                <cylinder radius="0.1" length="0.05" />
            </geometry>
            <material name="black">
                <color rgba="0.0 0.0 0.0 1.0" />
            </material>
        </visual>
        <collision>
            <origin xyz="0 0 0" rpy="0 0 0" />
            <geometry>
                <cylinder radius="0.1" length="0.05" />
            </geometry>
        </collision>
    </link>

    <link name="caster_wheel_link" type="continuous">
        <inertial>
            <origin xyz="-0.018729 -0.021844 -0.00089423" rpy="0 0 0" />
            <mass value="0.37834" />
            <inertia ixx="0.0004869" ixy="-8.4E-05" ixz="4.7177E-08" iyy="0.00045025"
                iyz="-4.7046E-07" izz="0.00064534" />
        </inertial>
        <visual>
            <origin xyz="0 0 0" rpy="0 0 0" />
            <geometry>
                <sphere radius="0.038" />
            </geometry>
            <material name="black">
                <color rgba="0.0 0.0 0.0 1.0" />
            </material>
        </visual>
        <collision>
            <origin xyz="0 0 0" rpy="0 0 0" />
            <geometry>
                <sphere radius="0.038" />
            </geometry>
        </collision>
    </link>

    <!-- Define joints -->
    <joint name="base_joint" type="fixed">
        <parent link="base_footprint" />
        <child link="base_link" />
        <origin xyz="0 0 ${wheel_radius}" rpy="0 0 0" />
    </joint>

    <joint name="base_right_wheel_joint" type="continuous">
        <parent link="base_link" />
        <child link="right_wheel_link" />
        <origin xyz="-0.19983 -0.34296 0.031554" rpy="-1.5708 0 0" />
        <axis xyz="0 0 1" />
        <dynamics damping="0.1" friction="0.1" />
    </joint>

    <joint name="base_left_wheel_joint" type="continuous">
        <parent link="base_link" />
        <child link="left_wheel_link" />
        <origin xyz="-0.19955 0.34249 0.034349" rpy="-1.5708 0 0" />
        <axis xyz="0 0 1" />
        <dynamics damping="0.1" friction="0.1" />
    </joint>

    <joint name="base_caster_wheel_joint" type="fixed">
        <parent link="base_link" />
        <child link="caster_wheel_link" />
        <origin xyz="0.24913 0.001 -0.0285" rpy="-1.5708 0 0" />
        <axis xyz="0 0 1" />
        <dynamics damping="0.1" friction="0.1" />
    </joint>


    <!-- ros2_control -->
    <ros2_control name="GazeboSystem" type="system">
        <hardware>
            <plugin>gazebo_ros2_control/GazeboSystem</plugin>
        </hardware>
        <joint name="base_left_wheel_joint">
            <command_interface name="velocity" />
            <state_interface name="position" />
            <state_interface name="velocity" />
        </joint>
        <joint name="base_right_wheel_joint">
            <command_interface name="velocity" />
            <state_interface name="position" />
            <state_interface name="velocity" />
        </joint>
    </ros2_control>

    <!-- Gazebo plugin -->
    <gazebo>
        <plugin name="gazebo_ros2_control" filename="libgazebo_ros2_control.so">
            <robot_namespace>/my_robot</robot_namespace>
        </plugin>
    </gazebo>
</robot>